Workbook
Name NativeTimeline_Date: #N/A
Name Slicer_City_Region: #N/A
Name Slicer_CustomerSegment: #N/A
Name Slicer_PurchaseChannel: #N/A

Sheet Dashboard
B2: 📊 MARKET RESEARCH & CUSTOMER SEGMENTATION DASHBOARD | FY 2025–26 | Apr 2025 – Mar 2026
B4: 👥 Total Customers | D4: 💰 Total Revenue (INR) | F4: 🛒 Avg Order Value (INR) | H4: 🔄 Repeat Customer % | J4: ⚠️ At-Risk Customers | L4: ⭐ Loyal Customers | N4: 📈 Avg Satisfaction
B5: ='KPI Summary'!B3 -> 200 | D5: ='KPI Summary'!B11 -> 10038773 | F5: ='KPI Summary'!B12 -> 9615.683 | H5: ='KPI Summary'!B24 -> 0.575 | J5: ='KPI Summary'!B33 -> 38 | L5: ='KPI Summary'!B27 -> 17 | N5: ='KPI Summary'!B42 -> 3.18625
B9: 📊 CHARTS & VISUALIZATIONS — Step 2: Insert Pivot Charts Here
B10: 📊 BAR CHART PLACEHOLDER Customers by Segment [ Insert Pivot Chart — Step 2 ] Source: tblFinal Rows: CustomerSegment Values: Count of CustomerID | I10: 📊 COLUMN CHART PLACEHOLDER Revenue by Segment [ Insert Pivot Chart — Step 2 ] Source: tblFinal Rows: CustomerSegment Values: Sum of RFM_Monetary
R25: x
B26: 🍩 DISTRIBUTION CHARTS — Step 2: Add Donut & Line Charts
B27: 🍩 DONUT CHART Customer Distribution [ Step 2 ] | F27: 📈 LINE CHART Monthly Revenue Trend [ Step 2 ] | J27: 📊 PIVOT TABLE Region-wise Analysis [ Step 2 ] | N27: ⚙️ SLICERS Segment Region Channel [ Step 2 ]
B41: 📋 KPI REFERENCE TABLE (Live — Updates from KPI Summary sheet)
B42: Metric | C42: Value | D42: Metric | E42: Value | F42: Metric | G42: Value | H42: Metric | I42: Value
B43: Total Customers | C43: ='KPI Summary'!B3 -> 200 | D43: Total Transactions | E43: ='KPI Summary'!B4 -> 1044 | F43: Total Revenue | G43: ='KPI Summary'!B11 -> 10038773 | H43: Avg AOV | I43: ='KPI Summary'!B12 -> 9615.683
B44: Repeat Customer % | C44: ='KPI Summary'!B24 -> 0.575 | D44: Loyal Customers | E44: ='KPI Summary'!B27 -> 17 | F44: At-Risk Customers | G44: ='KPI Summary'!B33 -> 38 | H44: Avg Satisfaction | I44: ='KPI Summary'!B42 -> 3.18625
B45: High Value Customers | C45: ='KPI Summary'!B25 -> 74 | D45: Online Revenue % | E45: ='KPI Summary'!B15 -> 0.47186255 | F45: Active Customers | G45: ='KPI Summary'!B22 -> 78 | H45: Low Engagement | I45: ='KPI Summary'!B35 -> 57
B48: 📋 SEGMENT PERFORMANCE SUMMARY (Live)
B49: Segment | C49: Customers | E49: Total Revenue | G49: Revenue % | I49: Avg Spend | K49: Status
B50: Loyal | C50: =COUNTIFS(tblFinal[CustomerSegment],B50) -> 17 | E50: =TEXT(IFERROR(SUMIFS(tblFinal[RFM_Monetary],tblFinal[CustomerSegment],B50),0),"#,##0") -> 15,25,892 | G50: {=TEXT(IFERROR(SUMPRODUCT((tblFinal[CustomerSegment]=B50)*SUMIFS(tblTransactions[Amount (INR)],tblTransactions[CustomerID],tblFinal[CustomerID]))/SUM(tblTransactions[Amount (INR)]),0),"0.0%")} -> 15.2% | I50: {=TEXT(IFERROR(SUMPRODUCT((tblFinal[CustomerSegment]=B50)*SUMIFS(tblTransactions[Amount (INR)],tblTransactions[CustomerID],tblFinal[CustomerID]))/COUNTIFS(tblFinal[CustomerSegment],B50),0),"#,##0")} -> 89,758 | K50: ⭐ Retain
B51: High Value | C51: =COUNTIFS(tblFinal[CustomerSegment],B51) -> 74 | E51: =TEXT(IFERROR(SUMIFS(tblFinal[RFM_Monetary],tblFinal[CustomerSegment],B51),0),"#,##0") -> 66,07,484 | G51: {=TEXT(IFERROR(SUMPRODUCT((tblFinal[CustomerSegment]=B51)*SUMIFS(tblTransactions[Amount (INR)],tblTransactions[CustomerID],tblFinal[CustomerID]))/SUM(tblTransactions[Amount (INR)]),0),"0.0%")} -> 65.8% | I51: {=TEXT(IFERROR(SUMPRODUCT((tblFinal[CustomerSegment]=B51)*SUMIFS(tblTransactions[Amount (INR)],tblTransactions[CustomerID],tblFinal[CustomerID]))/COUNTIFS(tblFinal[CustomerSegment],B51),0),"#,##0")} -> 89,290 | K51: 💎 Upsell
B52: At Risk | C52: =COUNTIFS(tblFinal[CustomerSegment],B52) -> 38 | E52: =TEXT(IFERROR(SUMIFS(tblFinal[RFM_Monetary],tblFinal[CustomerSegment],B52),0),"#,##0") -> 5,37,567 | G52: {=TEXT(IFERROR(SUMPRODUCT((tblFinal[CustomerSegment]=B52)*SUMIFS(tblTransactions[Amount (INR)],tblTransactions[CustomerID],tblFinal[CustomerID]))/SUM(tblTransactions[Amount (INR)]),0),"0.0%")} -> 5.4% | I52: {=TEXT(IFERROR(SUMPRODUCT((tblFinal[CustomerSegment]=B52)*SUMIFS(tblTransactions[Amount (INR)],tblTransactions[CustomerID],tblFinal[CustomerID]))/COUNTIFS(tblFinal[CustomerSegment],B52),0),"#,##0")} -> 14,147 | K52: ⚠️ Re-engage
B53: Bargain Seeker | C53: =COUNTIFS(tblFinal[CustomerSegment],B53) -> 8 | E53: =TEXT(IFERROR(SUMIFS(tblFinal[RFM_Monetary],tblFinal[CustomerSegment],B53),0),"#,##0") -> 1,84,330 | G53: {=TEXT(IFERROR(SUMPRODUCT((tblFinal[CustomerSegment]=B53)*SUMIFS(tblTransactions[Amount (INR)],tblTransactions[CustomerID],tblFinal[CustomerID]))/SUM(tblTransactions[Amount (INR)]),0),"0.0%")} -> 1.8% | I53: {=TEXT(IFERROR(SUMPRODUCT((tblFinal[CustomerSegment]=B53)*SUMIFS(tblTransactions[Amount (INR)],tblTransactions[CustomerID],tblFinal[CustomerID]))/COUNTIFS(tblFinal[CustomerSegment],B53),0),"#,##0")} -> 23,041 | K53: 🏷️ Nurture
B54: General | C54: =COUNTIFS(tblFinal[CustomerSegment],B54) -> 63 | E54: =TEXT(IFERROR(SUMIFS(tblFinal[RFM_Monetary],tblFinal[CustomerSegment],B54),0),"#,##0") -> 11,83,500 | G54: {=TEXT(IFERROR(SUMPRODUCT((tblFinal[CustomerSegment]=B54)*SUMIFS(tblTransactions[Amount (INR)],tblTransactions[CustomerID],tblFinal[CustomerID]))/SUM(tblTransactions[Amount (INR)]),0),"0.0%")} -> 11.8% | I54: {=TEXT(IFERROR(SUMPRODUCT((tblFinal[CustomerSegment]=B54)*SUMIFS(tblTransactions[Amount (INR)],tblTransactions[CustomerID],tblFinal[CustomerID]))/COUNTIFS(tblFinal[CustomerSegment],B54),0),"#,##0")} -> 18,786 | K54: 📌 Grow
B60: 📈 Pivot 5 — Analysis by Region | Source: tblTransactions
B61: Row Labels | C61: Count of CustomerID | D61: Sum of RFM_Monetary
B62: Ahmedabad | C62: 19 | D62: 666456
B63: Bangalore | C63: 14 | D63: 792765
B64: Bhopal | C64: 9 | D64: 479969
B65: Bhubaneswar | C65: 11 | D65: 663318
B66: Chandigarh | C66: 8 | D66: 445218
B67: Chennai | C67: 11 | D67: 751340
B68: Coimbatore | C68: 4 | D68: 207197
B69: Delhi | C69: 8 | D69: 275789
B70: Faridabad | C70: 2 | D70: 18490
B71: Gurgaon | C71: 2 | D71: 111010
B72: Hyderabad | C72: 8 | D72: 396008
B73: Indore | C73: 9 | D73: 405192
... B85: Grand Total | C85: 200 | D85: 10038773

Sheet Raw Data
A1: 📋 tblCustomers — Master Customer Data | O1: 💳 tblTransactions — Transaction Records | U1: 📝 tblSurvey — Customer Survey Responses
A2: CustomerID | B2: Name | C2: Gender | D2: Age | E2: City/Region | F2: IncomeRange | G2: Occupation | H2: JoinDate | I2: PurchaseChannel | J2: CustomerType | K2: EngagementLevel | L2: DiscountSensitivity | M2: LastPurchaseDate | N2: — | O2: TransactionID | P2: CustomerID | Q2: Date | R2: ProductCategory | S2: Amount (INR) | T2: — | U2: TxnMonth | V2: SurveyID | W2: CustomerID | X2: Satisfaction | Y2: PreferredChannel | Z2: RecommendationLikelihood
A3: C0001 | B3: Arjun Sharma | C3: Male | D3: 59 | E3: Noida | F3: 23278 | G3: Finance Analyst | H3: 45125 | I3: Online | J3: New | K3: Low | L3: High | M3: 46085 | O3: T00001 | P3: C0001 | Q3: 46085 | R3: Beauty | S3: 10900 | U3: =TEXT(tblTransactions[[#This Row],[Date]],"YYYY-MM") -> 2026-03 | V3: S0001 | W3: C0001 | X3: 4 | Y3: Online | Z3: 8
A4: C0002 | B4: Vikram Singh | C4: Male | D4: 53 | E4: Bangalore | F4: 97397 | G4: HR Manager | H4: 44627 | I4: Online | J4: New | K4: Medium | L4: Low | M4: 46043 | O4: T00002 | P4: C0002 | Q4: 46043 | R4: Grocery | S4: 3780 | U4: =TEXT(tblTransactions[[#This Row],[Date]],"YYYY-MM") -> 2026-01 | V4: S0002 | W4: C0002 | X4: 3 | Y4: Online | Z4: 6
A5: C0003 | B5: Rohan Mehta | C5: Male | D5: 31 | E5: Indore | F5: 74987 | G5: Doctor | H5: 45481 | I5: Online | J5: Returning | K5: Low | L5: High | M5: 45953 | O5: T00003 | P5: C0003 | Q5: 45942 | R5: Grocery | S5: 1950 | U5: =TEXT(tblTransactions[[#This Row],[Date]],"YYYY-MM") -> 2025-10 | V5: S0003 | W5: C0003 | X5: 4 | Y5: Online | Z5: 7
A6: C0004 | B6: Nikhil Gupta | C6: Male | D6: 46 | E6: Jaipur | F6: 56421 | G6: Teacher | H6: 45002 | I6: Offline | J6: New | K6: Low | L6: Low | M6: 46074 | O6: T00004 | P6: C0003 | Q6: 45953 | R6: Grocery | S6: 3430 | U6: =TEXT(tblTransactions[[#This Row],[Date]],"YYYY-MM") -> 2025-10 | V6: S0004 | W6: C0004 | X6: 3 | Y6: Offline | Z6: 6
A7: C0005 | B7: Amit Verma | C7: Male | D7: 41 | E7: Bhubaneswar | F7: 54671 | G7: Operations Manager | H7: 44650 | I7: Offline | J7: Returning | K7: High | L7: Medium | M7: 46013 | O7: T00005 | P7: C0004 | Q7: 46074 | R7: Electronics | S7: 12070 | U7: =TEXT(tblTransactions[[#This Row],[Date]],"YYYY-MM") -> 2026-02 | V7: S0005 | W7: C0005 | X7: 4 | Y7: Offline | Z7: 4
A8: C0006 | B8: Suresh Kumar | C8: Male | D8: 54 | E8: Kolkata | F8: 128711 | G8: Consultant | H8: 45302 | I8: Online | J8: Returning | K8: Low | L8: Low | M8: 45960 | O8: T00006 | P8: C0005 | Q8: 45933 | R8: Home Decor | S8: 1470 | U8: =TEXT(tblTransactions[[#This Row],[Date]],"YYYY-MM") -> 2025-10 | V8: S0006 | W8: C0006 | X8: 4 | Y8: Online | Z8: 7
A9: C0007 | B9: Rajesh Patel | C9: Male | D9: 37 | E9: Bangalore | F9: 132108 | G9: Doctor | H9: 44768 | I9: Online | J9: Returning | K9: High | L9: Low | M9: 45900 | O9: T00007 | P9: C0005 | Q9: 46003 | R9: Clothing | S9: 1730 | U9: =TEXT(tblTransactions[[#This Row],[Date]],"YYYY-MM") -> 2025-12 | V9: S0007 | W9: C0007 | X9: 4 | Y9: Online | Z9: 4
A10: C0008 | B10: Aditya Joshi | C10: Male | D10: 41 | E10: Hyderabad | F10: 107841 | G10: Business Owner | H10: 44708 | I10: Offline | J10: New | K10: Medium | L10: Low | M10: 46032 | O10: T00008 | P10: C0005 | Q10: 45884 | R10: Home Decor | S10: 1730 | U10: =TEXT(tblTransactions[[#This Row],[Date]],"YYYY-MM") -> 2025-08 | V10: S0008 | W10: C0008 | X10: 1 | Y10: Offline | Z10: 5
A11: C0009 | B11: Karan Kapoor | C11: Male | D11: 43 | E11: Ahmedabad | F11: 149698 | G11: Entrepreneur | H11: 45702 | I11: Online | J11: New | K11: High | L11: Low | M11: 46033 | O11: T00009 | P11: C0005 | Q11: 45815 | R11: Sports | S11: 9740 | U11: =TEXT(tblTransactions[[#This Row],[Date]],"YYYY-MM") -> 2025-06 | V11: S0009 | W11: C0009 | X11: 4 | Y11: Online | Z11: 9
A12: C0010 | B12: Deepak Nair | C12: Male | D12: 21 | E12: Jaipur | F12: 72581 | G12: Business Owner | H12: 44697 | I12: Online | J12: Returning | K12: High | L12: Medium | M12: 46085 | O12: T00010 | P12: C0005 | Q12: 45996 | R12: Electronics | S12: 3090 | U12: =TEXT(tblTransactions[[#This Row],[Date]],"YYYY-MM") -> 2025-12 | V12: S0010 | W12: C0010 | X12: 3 | Y12: Online | Z12: 6
A13: C0011 | B13: Manish Tiwari | C13: Male | D13: 60 | E13: Bhopal | F13: 71856 | G13: Entrepreneur | H13: 45501 | I13: Online | J13: New | K13: Medium | L13: Medium | M13: 46059 | O13: T00011 | P13: C0005 | Q13: 45762 | R13: Clothing | S13: 13260 | U13: =TEXT(tblTransactions[[#This Row],[Date]],"YYYY-MM") -> 2025-04 | V13: S0011 | W13: C0011 | X13: 4 | Y13: Online | Z13: 8
A14: C0012 | B14: Gaurav Saxena | C14: Male | D14: 56 | E14: Lucknow | F14: 137679 | G14: Retail Manager | H14: 45379 | I14: Online | J14: Returning | K14: Low | L14: Medium | M14: 45965 | O14: T00012 | P14: C0005 | Q14: 45829 | R14: Grocery | S14: 3740 | U14: =TEXT(tblTransactions[[#This Row],[Date]],"YYYY-MM") -> 2025-06 | V14: S0012 | W14: C0012 | X14: 4 | Y14: Online | Z14: 8
... A202: C0200 | B202: Manoj Pillai | C202: Male | D202: 35 | E202: Lucknow | F202: 73373 | G202: Consultant | H202: 45578 | I202: Offline | J202: Returning | K202: Medium | L202: Low | M202: 45751 | O202: T00200 | P202: C0045 | Q202: 45943 | R202: Home Decor | S202: 4130 | U202: =TEXT(tblTransactions[[#This Row],[Date]],"YYYY-MM") -> 2025-10 | V202: S0200 | W202: C0200 | X202: 1 | Y202: Online | Z202: 10
O203: T00201 | P203: C0045 | Q203: 46018 | R203: Clothing | S203: 2970 | U203: =TEXT(tblTransactions[[#This Row],[Date]],"YYYY-MM") -> 2025-12
O204: T00202 | P204: C0045 | Q204: 46057 | R204: Clothing | S204: 5680 | U204: =TEXT(tblTransactions[[#This Row],[Date]],"YYYY-MM") -> 2026-02
O205: T00203 | P205: C0045 | Q205: 45876 | R205: Grocery | S205: 10710 | U205: =TEXT(tblTransactions[[#This Row],[Date]],"YYYY-MM") -> 2025-08
O206: T00204 | P206: C0045 | Q206: 46031 | R206: Electronics | S206: 6040 | U206: =TEXT(tblTransactions[[#This Row],[Date]],"YYYY-MM") -> 2026-01
O207: T00205 | P207: C0045 | Q207: 46080 | R207: Electronics | S207: 3570 | U207: =TEXT(tblTransactions[[#This Row],[Date]],"YYYY-MM") -> 2026-02
O208: T00206 | P208: C0046 | Q208: 45823 | R208: Beauty | S208: 1770 | U208: =TEXT(tblTransactions[[#This Row],[Date]],"YYYY-MM") -> 2025-06
O209: T00207 | P209: C0046 | Q209: 45794 | R209: Beauty | S209: 7680 | U209: =TEXT(tblTransactions[[#This Row],[Date]],"YYYY-MM") -> 2025-05
O210: T00208 | P210: C0046 | Q210: 45926 | R210: Electronics | S210: 3730 | U210: =TEXT(tblTransactions[[#This Row],[Date]],"YYYY-MM") -> 2025-09
O211: T00209 | P211: C0046 | Q211: 45960 | R211: Clothing | S211: 10980 | U211: =TEXT(tblTransactions[[#This Row],[Date]],"YYYY-MM") -> 2025-10
O212: T00210 | P212: C0046 | Q212: 45945 | R212: Electronics | S212: 6140 | U212: =TEXT(tblTransactions[[#This Row],[Date]],"YYYY-MM") -> 2025-10
O213: T00211 | P213: C0046 | Q213: 45939 | R213: Electronics | S213: 5030 | U213: =TEXT(tblTransactions[[#This Row],[Date]],"YYYY-MM") -> 2025-10
O214: T00212 | P214: C0046 | Q214: 45919 | R214: Clothing | S214: 8990 | U214: =TEXT(tblTransactions[[#This Row],[Date]],"YYYY-MM") -> 2025-09
... O1046: T01045 | P1046: C0200 | Q1046: 45955 | R1046: Home Decor | S1046: 6544 | U1046: =TEXT(tblTransactions[[#This Row],[Date]],"YYYY-MM") -> 2025-10

Sheet Cleaned Data
A1: 🧹 tblClean — Cleaned Customer Data with Derived Columns (Formula-Driven from tblCustomers)
A2: CustomerID | B2: Name (Cleaned) | C2: Gender | D2: Age | E2: City/Region (Cleaned) | F2: IncomeRange | G2: Occupation (Cleaned) | H2: JoinDate | I2: PurchaseChannel | J2: CustomerType | K2: EngagementLevel | L2: DiscountSensitivity | M2: LastPurchaseDate | N2: AgeGroup | O2: IncomeBracket | P2: DayOfJoin | Q2: IsWeekend_Join | R2: MonthsAsCustomer | S2: DataFlag
A3: =IFERROR(TRIM(tblCustomers[[#This Row],[CustomerID]]),"") -> C0001 | B3: =IFERROR(PROPER(TRIM(tblCustomers[[#This Row],[Name]])),"") -> Arjun Sharma | C3: =IFERROR(PROPER(TRIM(tblCustomers[[#This Row],[Gender]])),"") -> Male | D3: =IFERROR(tblCustomers[[#This Row],[Age]],"") -> 59 | E3: =IFERROR(PROPER(TRIM(tblCustomers[[#This Row],[City/Region]])),"") -> Noida | F3: =IFERROR(tblCustomers[[#This Row],[IncomeRange]],"") -> 23278 | G3: =IFERROR(PROPER(TRIM(tblCustomers[[#This Row],[Occupation]])),"") -> Finance Analyst | H3: =IFERROR(tblCustomers[[#This Row],[JoinDate]],"") -> 45125 | I3: =IFERROR(PROPER(TRIM(tblCustomers[[#This Row],[PurchaseChannel]])),"") -> Online | J3: =IFERROR(PROPER(TRIM(tblCustomers[[#This Row],[CustomerType]])),"") -> New | K3: =IFERROR(PROPER(TRIM(tblCustomers[[#This Row],[EngagementLevel]])),"") -> Low | L3: =IFERROR(PROPER(TRIM(tblCustomers[[#This Row],[DiscountSensitivity]])),"") -> High | M3: =IFERROR(tblCustomers[[#This Row],[LastPurchaseDate]],"") -> 46085 | N3: =IFERROR(IF(tblCustomers[[#This Row],[Age]]<25,"<25",IF(tblCustomers[[#This Row],[Age]]<40,"25-39",IF(tblCustomers[[#This Row],[Age]]<55,"40-54","55+"))),"N/A") -> 55+ | O3: =IFERROR(IF(tblCustomers[[#This Row],[IncomeRange]]<25000,"Low",IF(tblCustomers[[#This Row],[IncomeRange]]<75000,"Mid","High")),"N/A") -> Low | P3: =IFERROR(TEXT(tblCustomers[[#This Row],[JoinDate]],"DDDD"),"") -> Tuesday | Q3: =IFERROR(IF(WEEKDAY(tblCustomers[[#This Row],[JoinDate]],2)>=6,TRUE(),FALSE()),FALSE()) -> FALSE | R3: =IFERROR(DATEDIF(tblCustomers[[#This Row],[JoinDate]],TODAY(),"M"),0) -> 32 | S3: =IFERROR(IF(AND(tblCustomers[[#This Row],[Age]]>=18,tblCustomers[[#This Row],[IncomeRange]]>0,tblCustomers[[#This Row],[CustomerID]]<>""),"OK","CHECK"),"CHECK") -> OK
A4: =IFERROR(TRIM(tblCustomers[[#This Row],[CustomerID]]),"") -> C0002 | B4: =IFERROR(PROPER(TRIM(tblCustomers[[#This Row],[Name]])),"") -> Vikram Singh | C4: =IFERROR(PROPER(TRIM(tblCustomers[[#This Row],[Gender]])),"") -> Male | D4: =IFERROR(tblCustomers[[#This Row],[Age]],"") -> 53 | E4: =IFERROR(PROPER(TRIM(tblCustomers[[#This Row],[City/Region]])),"") -> Bangalore | F4: =IFERROR(tblCustomers[[#This Row],[IncomeRange]],"") -> 97397 | G4: =IFERROR(PROPER(TRIM(tblCustomers[[#This Row],[Occupation]])),"") -> Hr Manager | H4: =IFERROR(tblCustomers[[#This Row],[JoinDate]],"") -> 44627 | I4: =IFERROR(PROPER(TRIM(tblCustomers[[#This Row],[PurchaseChannel]])),"") -> Online | J4: =IFERROR(PROPER(TRIM(tblCustomers[[#This Row],[CustomerType]])),"") -> New | K4: =IFERROR(PROPER(TRIM(tblCustomers[[#This Row],[EngagementLevel]])),"") -> Medium | L4: =IFERROR(PROPER(TRIM(tblCustomers[[#This Row],[DiscountSensitivity]])),"") -> Low | M4: =IFERROR(tblCustomers[[#This Row],[LastPurchaseDate]],"") -> 46043 | N4: =IFERROR(IF(tblCustomers[[#This Row],[Age]]<25,"<25",IF(tblCustomers[[#This Row],[Age]]<40,"25-39",IF(tblCustomers[[#This Row],[Age]]<55,"40-54","55+"))),"N/A") -> 40-54 | O4: =IFERROR(IF(tblCustomers[[#This Row],[IncomeRange]]<25000,"Low",IF(tblCustomers[[#This Row],[IncomeRange]]<75000,"Mid","High")),"N/A") -> High | P4: =IFERROR(TEXT(tblCustomers[[#This Row],[JoinDate]],"DDDD"),"") -> Monday | Q4: =IFERROR(IF(WEEKDAY(tblCustomers[[#This Row],[JoinDate]],2)>=6,TRUE(),FALSE()),FALSE()) -> FALSE | R4: =IFERROR(DATEDIF(tblCustomers[[#This Row],[JoinDate]],TODAY(),"M"),0) -> 49 | S4: =IFERROR(IF(AND(tblCustomers[[#This Row],[Age]]>=18,tblCustomers[[#This Row],[IncomeRange]]>0,tblCustomers[[#This Row],[CustomerID]]<>""),"OK","CHECK"),"CHECK") -> OK
A5: =IFERROR(TRIM(tblCustomers[[#This Row],[CustomerID]]),"") -> C0003 | B5: =IFERROR(PROPER(TRIM(tblCustomers[[#This Row],[Name]])),"") -> Rohan Mehta | C5: =IFERROR(PROPER(TRIM(tblCustomers[[#This Row],[Gender]])),"") -> Male | D5: =IFERROR(tblCustomers[[#This Row],[Age]],"") -> 31 | E5: =IFERROR(PROPER(TRIM(tblCustomers[[#This Row],[City/Region]])),"") -> Indore | F5: =IFERROR(tblCustomers[[#This Row],[IncomeRange]],"") -> 74987 | G5: =IFERROR(PROPER(TRIM(tblCustomers[[#This Row],[Occupation]])),"") -> Doctor | H5: =IFERROR(tblCustomers[[#This Row],[JoinDate]],"") -> 45481 | I5: =IFERROR(PROPER(TRIM(tblCustomers[[#This Row],[PurchaseChannel]])),"") -> Online | J5: =IFERROR(PROPER(TRIM(tblCustomers[[#This Row],[CustomerType]])),"") -> Returning | K5: =IFERROR(PROPER(TRIM(tblCustomers[[#This Row],[EngagementLevel]])),"") -> Low | L5: =IFERROR(PROPER(TRIM(tblCustomers[[#This Row],[DiscountSensitivity]])),"") -> High | M5: =IFERROR(tblCustomers[[#This Row],[LastPurchaseDate]],"") -> 45953 | N5: =IFERROR(IF(tblCustomers[[#This Row],[Age]]<25,"<25",IF(tblCustomers[[#This Row],[Age]]<40,"25-39",IF(tblCustomers[[#This Row],[Age]]<55,"40-54","55+"))),"N/A") -> 25-39 | O5: =IFERROR(IF(tblCustomers[[#This Row],[IncomeRange]]<25000,"Low",IF(tblCustomers[[#This Row],[IncomeRange]]<75000,"Mid","High")),"N/A") -> Mid | P5: =IFERROR(TEXT(tblCustomers[[#This Row],[JoinDate]],"DDDD"),"") -> Monday | Q5: =IFERROR(IF(WEEKDAY(tblCustomers[[#This Row],[JoinDate]],2)>=6,TRUE(),FALSE()),FALSE()) -> FALSE | R5: =IFERROR(DATEDIF(tblCustomers[[#This Row],[JoinDate]],TODAY(),"M"),0) -> 21 | S5: =IFERROR(IF(AND(tblCustomers[[#This Row],[Age]]>=18,tblCustomers[[#This Row],[IncomeRange]]>0,tblCustomers[[#This Row],[CustomerID]]<>""),"OK","CHECK"),"CHECK") -> OK
A6: =IFERROR(TRIM(tblCustomers[[#This Row],[CustomerID]]),"") -> C0004 | B6: =IFERROR(PROPER(TRIM(tblCustomers[[#This Row],[Name]])),"") -> Nikhil Gupta | C6: =IFERROR(PROPER(TRIM(tblCustomers[[#This Row],[Gender]])),"") -> Male | D6: =IFERROR(tblCustomers[[#This Row],[Age]],"") -> 46 | E6: =IFERROR(PROPER(TRIM(tblCustomers[[#This Row],[City/Region]])),"") -> Jaipur | F6: =IFERROR(tblCustomers[[#This Row],[IncomeRange]],"") -> 56421 | G6: =IFERROR(PROPER(TRIM(tblCustomers[[#This Row],[Occupation]])),"") -> Teacher | H6: =IFERROR(tblCustomers[[#This Row],[JoinDate]],"") -> 45002 | I6: =IFERROR(PROPER(TRIM(tblCustomers[[#This Row],[PurchaseChannel]])),"") -> Offline | J6: =IFERROR(PROPER(TRIM(tblCustomers[[#This Row],[CustomerType]])),"") -> New | K6: =IFERROR(PROPER(TRIM(tblCustomers[[#This Row],[EngagementLevel]])),"") -> Low | L6: =IFERROR(PROPER(TRIM(tblCustomers[[#This Row],[DiscountSensitivity]])),"") -> Low | M6: =IFERROR(tblCustomers[[#This Row],[LastPurchaseDate]],"") -> 46074 | N6: =IFERROR(IF(tblCustomers[[#This Row],[Age]]<25,"<25",IF(tblCustomers[[#This Row],[Age]]<40,"25-39",IF(tblCustomers[[#This Row],[Age]]<55,"40-54","55+"))),"N/A") -> 40-54 | O6: =IFERROR(IF(tblCustomers[[#This Row],[IncomeRange]]<25000,"Low",IF(tblCustomers[[#This Row],[IncomeRange]]<75000,"Mid","High")),"N/A") -> Mid | P6: =IFERROR(TEXT(tblCustomers[[#This Row],[JoinDate]],"DDDD"),"") -> Friday | Q6: =IFERROR(IF(WEEKDAY(tblCustomers[[#This Row],[JoinDate]],2)>=6,TRUE(),FALSE()),FALSE()) -> FALSE | R6: =IFERROR(DATEDIF(tblCustomers[[#This Row],[JoinDate]],TODAY(),"M"),0) -> 36 | S6: =IFERROR(IF(AND(tblCustomers[[#This Row],[Age]]>=18,tblCustomers[[#This Row],[IncomeRange]]>0,tblCustomers[[#This Row],[CustomerID]]<>""),"OK","CHECK"),"CHECK") -> OK
A7: =IFERROR(TRIM(tblCustomers[[#This Row],[CustomerID]]),"") -> C0005 | B7: =IFERROR(PROPER(TRIM(tblCustomers[[#This Row],[Name]])),"") -> Amit Verma | C7: =IFERROR(PROPER(TRIM(tblCustomers[[#This Row],[Gender]])),"") -> Male | D7: =IFERROR(tblCustomers[[#This Row],[Age]],"") -> 41 | E7: =IFERROR(PROPER(TRIM(tblCustomers[[#This Row],[City/Region]])),"") -> Bhubaneswar | F7: =IFERROR(tblCustomers[[#This Row],[IncomeRange]],"") -> 54671 | G7: =IFERROR(PROPER(TRIM(tblCustomers[[#This Row],[Occupation]])),"") -> Operations Manager | H7: =IFERROR(tblCustomers[[#This Row],[JoinDate]],"") -> 44650 | I7: =IFERROR(PROPER(TRIM(tblCustomers[[#This Row],[PurchaseChannel]])),"") -> Offline | J7: =IFERROR(PROPER(TRIM(tblCustomers[[#This Row],[CustomerType]])),"") -> Returning | K7: =IFERROR(PROPER(TRIM(tblCustomers[[#This Row],[EngagementLevel]])),"") -> High | L7: =IFERROR(PROPER(TRIM(tblCustomers[[#This Row],[DiscountSensitivity]])),"") -> Medium | M7: =IFERROR(tblCustomers[[#This Row],[LastPurchaseDate]],"") -> 46013 | N7: =IFERROR(IF(tblCustomers[[#This Row],[Age]]<25,"<25",IF(tblCustomers[[#This Row],[Age]]<40,"25-39",IF(tblCustomers[[#This Row],[Age]]<55,"40-54","55+"))),"N/A") -> 40-54 | O7: =IFERROR(IF(tblCustomers[[#This Row],[IncomeRange]]<25000,"Low",IF(tblCustomers[[#This Row],[IncomeRange]]<75000,"Mid","High")),"N/A") -> Mid | P7: =IFERROR(TEXT(tblCustomers[[#This Row],[JoinDate]],"DDDD"),"") -> Wednesday | Q7: =IFERROR(IF(WEEKDAY(tblCustomers[[#This Row],[JoinDate]],2)>=6,TRUE(),FALSE()),FALSE()) -> FALSE | R7: =IFERROR(DATEDIF(tblCustomers[[#This Row],[JoinDate]],TODAY(),"M"),0) -> 48 | S7: =IFERROR(IF(AND(tblCustomers[[#This Row],[Age]]>=18,tblCustomers[[#This Row],[IncomeRange]]>0,tblCustomers[[#This Row],[CustomerID]]<>""),"OK","CHECK"),"CHECK") -> OK
A8: =IFERROR(TRIM(tblCustomers[[#This Row],[CustomerID]]),"") -> C0006 | B8: =IFERROR(PROPER(TRIM(tblCustomers[[#This Row],[Name]])),"") -> Suresh Kumar | C8: =IFERROR(PROPER(TRIM(tblCustomers[[#This Row],[Gender]])),"") -> Male | D8: =IFERROR(tblCustomers[[#This Row],[Age]],"") -> 54 | E8: =IFERROR(PROPER(TRIM(tblCustomers[[#This Row],[City/Region]])),"") -> Kolkata | F8: =IFERROR(tblCustomers[[#This Row],[IncomeRange]],"") -> 128711 | G8: =IFERROR(PROPER(TRIM(tblCustomers[[#This Row],[Occupation]])),"") -> Consultant | H8: =IFERROR(tblCustomers[[#This Row],[JoinDate]],"") -> 45302 | I8: =IFERROR(PROPER(TRIM(tblCustomers[[#This Row],[PurchaseChannel]])),"") -> Online | J8: =IFERROR(PROPER(TRIM(tblCustomers[[#This Row],[CustomerType]])),"") -> Returning | K8: =IFERROR(PROPER(TRIM(tblCustomers[[#This Row],[EngagementLevel]])),"") -> Low | L8: =IFERROR(PROPER(TRIM(tblCustomers[[#This Row],[DiscountSensitivity]])),"") -> Low | M8: =IFERROR(tblCustomers[[#This Row],[LastPurchaseDate]],"") -> 45960 | N8: =IFERROR(IF(tblCustomers[[#This Row],[Age]]<25,"<25",IF(tblCustomers[[#This Row],[Age]]<40,"25-39",IF(tblCustomers[[#This Row],[Age]]<55,"40-54","55+"))),"N/A") -> 40-54 | O8: =IFERROR(IF(tblCustomers[[#This Row],[IncomeRange]]<25000,"Low",IF(tblCustomers[[#This Row],[IncomeRange]]<75000,"Mid","High")),"N/A") -> High | P8: =IFERROR(TEXT(tblCustomers[[#This Row],[JoinDate]],"DDDD"),"") -> Thursday | Q8: =IFERROR(IF(WEEKDAY(tblCustomers[[#This Row],[JoinDate]],2)>=6,TRUE(),FALSE()),FALSE()) -> FALSE | R8: =IFERROR(DATEDIF(tblCustomers[[#This Row],[JoinDate]],TODAY(),"M"),0) -> 27 | S8: =IFERROR(IF(AND(tblCustomers[[#This Row],[Age]]>=18,tblCustomers[[#This Row],[IncomeRange]]>0,tblCustomers[[#This Row],[CustomerID]]<>""),"OK","CHECK"),"CHECK") -> OK
A9: =IFERROR(TRIM(tblCustomers[[#This Row],[CustomerID]]),"") -> C0007 | B9: =IFERROR(PROPER(TRIM(tblCustomers[[#This Row],[Name]])),"") -> Rajesh Patel | C9: =IFERROR(PROPER(TRIM(tblCustomers[[#This Row],[Gender]])),"") -> Male | D9: =IFERROR(tblCustomers[[#This Row],[Age]],"") -> 37 | E9: =IFERROR(PROPER(TRIM(tblCustomers[[#This Row],[City/Region]])),"") -> Bangalore | F9: =IFERROR(tblCustomers[[#This Row],[IncomeRange]],"") -> 132108 | G9: =IFERROR(PROPER(TRIM(tblCustomers[[#This Row],[Occupation]])),"") -> Doctor | H9: =IFERROR(tblCustomers[[#This Row],[JoinDate]],"") -> 44768 | I9: =IFERROR(PROPER(TRIM(tblCustomers[[#This Row],[PurchaseChannel]])),"") -> Online | J9: =IFERROR(PROPER(TRIM(tblCustomers[[#This Row],[CustomerType]])),"") -> Returning | K9: =IFERROR(PROPER(TRIM(tblCustomers[[#This Row],[EngagementLevel]])),"") -> High | L9: =IFERROR(PROPER(TRIM(tblCustomers[[#This Row],[DiscountSensitivity]])),"") -> Low | M9: =IFERROR(tblCustomers[[#This Row],[LastPurchaseDate]],"") -> 45900 | N9: =IFERROR(IF(tblCustomers[[#This Row],[Age]]<25,"<25",IF(tblCustomers[[#This Row],[Age]]<40,"25-39",IF(tblCustomers[[#This Row],[Age]]<55,"40-54","55+"))),"N/A") -> 25-39 | O9: =IFERROR(IF(tblCustomers[[#This Row],[IncomeRange]]<25000,"Low",IF(tblCustomers[[#This Row],[IncomeRange]]<75000,"Mid","High")),"N/A") -> High | P9: =IFERROR(TEXT(tblCustomers[[#This Row],[JoinDate]],"DDDD"),"") -> Tuesday | Q9: =IFERROR(IF(WEEKDAY(tblCustomers[[#This Row],[JoinDate]],2)>=6,TRUE(),FALSE()),FALSE()) -> FALSE | R9: =IFERROR(DATEDIF(tblCustomers[[#This Row],[JoinDate]],TODAY(),"M"),0) -> 44 | S9: =IFERROR(IF(AND(tblCustomers[[#This Row],[Age]]>=18,tblCustomers[[#This Row],[IncomeRange]]>0,tblCustomers[[#This Row],[CustomerID]]<>""),"OK","CHECK"),"CHECK") -> OK
A10: =IFERROR(TRIM(tblCustomers[[#This Row],[CustomerID]]),"") -> C0008 | B10: =IFERROR(PROPER(TRIM(tblCustomers[[#This Row],[Name]])),"") -> Aditya Joshi | C10: =IFERROR(PROPER(TRIM(tblCustomers[[#This Row],[Gender]])),"") -> Male | D10: =IFERROR(tblCustomers[[#This Row],[Age]],"") -> 41 | E10: =IFERROR(PROPER(TRIM(tblCustomers[[#This Row],[City/Region]])),"") -> Hyderabad | F10: =IFERROR(tblCustomers[[#This Row],[IncomeRange]],"") -> 107841 | G10: =IFERROR(PROPER(TRIM(tblCustomers[[#This Row],[Occupation]])),"") -> Business Owner | H10: =IFERROR(tblCustomers[[#This Row],[JoinDate]],"") -> 44708 | I10: =IFERROR(PROPER(TRIM(tblCustomers[[#This Row],[PurchaseChannel]])),"") -> Offline | J10: =IFERROR(PROPER(TRIM(tblCustomers[[#This Row],[CustomerType]])),"") -> New | K10: =IFERROR(PROPER(TRIM(tblCustomers[[#This Row],[EngagementLevel]])),"") -> Medium | L10: =IFERROR(PROPER(TRIM(tblCustomers[[#This Row],[DiscountSensitivity]])),"") -> Low | M10: =IFERROR(tblCustomers[[#This Row],[LastPurchaseDate]],"") -> 46032 | N10: =IFERROR(IF(tblCustomers[[#This Row],[Age]]<25,"<25",IF(tblCustomers[[#This Row],[Age]]<40,"25-39",IF(tblCustomers[[#This Row],[Age]]<55,"40-54","55+"))),"N/A") -> 40-54 | O10: =IFERROR(IF(tblCustomers[[#This Row],[IncomeRange]]<25000,"Low",IF(tblCustomers[[#This Row],[IncomeRange]]<75000,"Mid","High")),"N/A") -> High | P10: =IFERROR(TEXT(tblCustomers[[#This Row],[JoinDate]],"DDDD"),"") -> Friday | Q10: =IFERROR(IF(WEEKDAY(tblCustomers[[#This Row],[JoinDate]],2)>=6,TRUE(),FALSE()),FALSE()) -> FALSE | R10: =IFERROR(DATEDIF(tblCustomers[[#This Row],[JoinDate]],TODAY(),"M"),0) -> 46 | S10: =IFERROR(IF(AND(tblCustomers[[#This Row],[Age]]>=18,tblCustomers[[#This Row],[IncomeRange]]>0,tblCustomers[[#This Row],[CustomerID]]<>""),"OK","CHECK"),"CHECK") -> OK
A11: =IFERROR(TRIM(tblCustomers[[#This Row],[CustomerID]]),"") -> C0009 | B11: =IFERROR(PROPER(TRIM(tblCustomers[[#This Row],[Name]])),"") -> Karan Kapoor | C11: =IFERROR(PROPER(TRIM(tblCustomers[[#This Row],[Gender]])),"") -> Male | D11: =IFERROR(tblCustomers[[#This Row],[Age]],"") -> 43 | E11: =IFERROR(PROPER(TRIM(tblCustomers[[#This Row],[City/Region]])),"") -> Ahmedabad | F11: =IFERROR(tblCustomers[[#This Row],[IncomeRange]],"") -> 149698 | G11: =IFERROR(PROPER(TRIM(tblCustomers[[#This Row],[Occupation]])),"") -> Entrepreneur | H11: =IFERROR(tblCustomers[[#This Row],[JoinDate]],"") -> 45702 | I11: =IFERROR(PROPER(TRIM(tblCustomers[[#This Row],[PurchaseChannel]])),"") -> Online | J11: =IFERROR(PROPER(TRIM(tblCustomers[[#This Row],[CustomerType]])),"") -> New | K11: =IFERROR(PROPER(TRIM(tblCustomers[[#This Row],[EngagementLevel]])),"") -> High | L11: =IFERROR(PROPER(TRIM(tblCustomers[[#This Row],[DiscountSensitivity]])),"") -> Low | M11: =IFERROR(tblCustomers[[#This Row],[LastPurchaseDate]],"") -> 46033 | N11: =IFERROR(IF(tblCustomers[[#This Row],[Age]]<25,"<25",IF(tblCustomers[[#This Row],[Age]]<40,"25-39",IF(tblCustomers[[#This Row],[Age]]<55,"40-54","55+"))),"N/A") -> 40-54 | O11: =IFERROR(IF(tblCustomers[[#This Row],[IncomeRange]]<25000,"Low",IF(tblCustomers[[#This Row],[IncomeRange]]<75000,"Mid","High")),"N/A") -> High | P11: =IFERROR(TEXT(tblCustomers[[#This Row],[JoinDate]],"DDDD"),"") -> Friday | Q11: =IFERROR(IF(WEEKDAY(tblCustomers[[#This Row],[JoinDate]],2)>=6,TRUE(),FALSE()),FALSE()) -> FALSE | R11: =IFERROR(DATEDIF(tblCustomers[[#This Row],[JoinDate]],TODAY(),"M"),0) -> 13 | S11: =IFERROR(IF(AND(tblCustomers[[#This Row],[Age]]>=18,tblCustomers[[#This Row],[IncomeRange]]>0,tblCustomers[[#This Row],[CustomerID]]<>""),"OK","CHECK"),"CHECK") -> OK
A12: =IFERROR(TRIM(tblCustomers[[#This Row],[CustomerID]]),"") -> C0010 | B12: =IFERROR(PROPER(TRIM(tblCustomers[[#This Row],[Name]])),"") -> Deepak Nair | C12: =IFERROR(PROPER(TRIM(tblCustomers[[#This Row],[Gender]])),"") -> Male | D12: =IFERROR(tblCustomers[[#This Row],[Age]],"") -> 21 | E12: =IFERROR(PROPER(TRIM(tblCustomers[[#This Row],[City/Region]])),"") -> Jaipur | F12: =IFERROR(tblCustomers[[#This Row],[IncomeRange]],"") -> 72581 | G12: =IFERROR(PROPER(TRIM(tblCustomers[[#This Row],[Occupation]])),"") -> Business Owner | H12: =IFERROR(tblCustomers[[#This Row],[JoinDate]],"") -> 44697 | I12: =IFERROR(PROPER(TRIM(tblCustomers[[#This Row],[PurchaseChannel]])),"") -> Online | J12: =IFERROR(PROPER(TRIM(tblCustomers[[#This Row],[CustomerType]])),"") -> Returning | K12: =IFERROR(PROPER(TRIM(tblCustomers[[#This Row],[EngagementLevel]])),"") -> High | L12: =IFERROR(PROPER(TRIM(tblCustomers[[#This Row],[DiscountSensitivity]])),"") -> Medium | M12: =IFERROR(tblCustomers[[#This Row],[LastPurchaseDate]],"") -> 46085 | N12: =IFERROR(IF(tblCustomers[[#This Row],[Age]]<25,"<25",IF(tblCustomers[[#This Row],[Age]]<40,"25-39",IF(tblCustomers[[#This Row],[Age]]<55,"40-54","55+"))),"N/A") -> <25 | O12: =IFERROR(IF(tblCustomers[[#This Row],[IncomeRange]]<25000,"Low",IF(tblCustomers[[#This Row],[IncomeRange]]<75000,"Mid","High")),"N/A") -> Mid | P12: =IFERROR(TEXT(tblCustomers[[#This Row],[JoinDate]],"DDDD"),"") -> Monday | Q12: =IFERROR(IF(WEEKDAY(tblCustomers[[#This Row],[JoinDate]],2)>=6,TRUE(),FALSE()),FALSE()) -> FALSE | R12: =IFERROR(DATEDIF(tblCustomers[[#This Row],[JoinDate]],TODAY(),"M"),0) -> 46 | S12: =IFERROR(IF(AND(tblCustomers[[#This Row],[Age]]>=18,tblCustomers[[#This Row],[IncomeRange]]>0,tblCustomers[[#This Row],[CustomerID]]<>""),"OK","CHECK"),"CHECK") -> OK
A13: =IFERROR(TRIM(tblCustomers[[#This Row],[CustomerID]]),"") -> C0011 | B13: =IFERROR(PROPER(TRIM(tblCustomers[[#This Row],[Name]])),"") -> Manish Tiwari | C13: =IFERROR(PROPER(TRIM(tblCustomers[[#This Row],[Gender]])),"") -> Male | D13: =IFERROR(tblCustomers[[#This Row],[Age]],"") -> 60 | E13: =IFERROR(PROPER(TRIM(tblCustomers[[#This Row],[City/Region]])),"") -> Bhopal | F13: =IFERROR(tblCustomers[[#This Row],[IncomeRange]],"") -> 71856 | G13: =IFERROR(PROPER(TRIM(tblCustomers[[#This Row],[Occupation]])),"") -> Entrepreneur | H13: =IFERROR(tblCustomers[[#This Row],[JoinDate]],"") -> 45501 | I13: =IFERROR(PROPER(TRIM(tblCustomers[[#This Row],[PurchaseChannel]])),"") -> Online | J13: =IFERROR(PROPER(TRIM(tblCustomers[[#This Row],[CustomerType]])),"") -> New | K13: =IFERROR(PROPER(TRIM(tblCustomers[[#This Row],[EngagementLevel]])),"") -> Medium | L13: =IFERROR(PROPER(TRIM(tblCustomers[[#This Row],[DiscountSensitivity]])),"") -> Medium | M13: =IFERROR(tblCustomers[[#This Row],[LastPurchaseDate]],"") -> 46059 | N13: =IFERROR(IF(tblCustomers[[#This Row],[Age]]<25,"<25",IF(tblCustomers[[#This Row],[Age]]<40,"25-39",IF(tblCustomers[[#This Row],[Age]]<55,"40-54","55+"))),"N/A") -> 55+ | O13: =IFERROR(IF(tblCustomers[[#This Row],[IncomeRange]]<25000,"Low",IF(tblCustomers[[#This Row],[IncomeRange]]<75000,"Mid","High")),"N/A") -> Mid | P13: =IFERROR(TEXT(tblCustomers[[#This Row],[JoinDate]],"DDDD"),"") -> Sunday | Q13: =IFERROR(IF(WEEKDAY(tblCustomers[[#This Row],[JoinDate]],2)>=6,TRUE(),FALSE()),FALSE()) -> TRUE | R13: =IFERROR(DATEDIF(tblCustomers[[#This Row],[JoinDate]],TODAY(),"M"),0) -> 20 | S13: =IFERROR(IF(AND(tblCustomers[[#This Row],[Age]]>=18,tblCustomers[[#This Row],[IncomeRange]]>0,tblCustomers[[#This Row],[CustomerID]]<>""),"OK","CHECK"),"CHECK") -> OK
A14: =IFERROR(TRIM(tblCustomers[[#This Row],[CustomerID]]),"") -> C0012 | B14: =IFERROR(PROPER(TRIM(tblCustomers[[#This Row],[Name]])),"") -> Gaurav Saxena | C14: =IFERROR(PROPER(TRIM(tblCustomers[[#This Row],[Gender]])),"") -> Male | D14: =IFERROR(tblCustomers[[#This Row],[Age]],"") -> 56 | E14: =IFERROR(PROPER(TRIM(tblCustomers[[#This Row],[City/Region]])),"") -> Lucknow | F14: =IFERROR(tblCustomers[[#This Row],[IncomeRange]],"") -> 137679 | G14: =IFERROR(PROPER(TRIM(tblCustomers[[#This Row],[Occupation]])),"") -> Retail Manager | H14: =IFERROR(tblCustomers[[#This Row],[JoinDate]],"") -> 45379 | I14: =IFERROR(PROPER(TRIM(tblCustomers[[#This Row],[PurchaseChannel]])),"") -> Online | J14: =IFERROR(PROPER(TRIM(tblCustomers[[#This Row],[CustomerType]])),"") -> Returning | K14: =IFERROR(PROPER(TRIM(tblCustomers[[#This Row],[EngagementLevel]])),"") -> Low | L14: =IFERROR(PROPER(TRIM(tblCustomers[[#This Row],[DiscountSensitivity]])),"") -> Medium | M14: =IFERROR(tblCustomers[[#This Row],[LastPurchaseDate]],"") -> 45965 | N14: =IFERROR(IF(tblCustomers[[#This Row],[Age]]<25,"<25",IF(tblCustomers[[#This Row],[Age]]<40,"25-39",IF(tblCustomers[[#This Row],[Age]]<55,"40-54","55+"))),"N/A") -> 55+ | O14: =IFERROR(IF(tblCustomers[[#This Row],[IncomeRange]]<25000,"Low",IF(tblCustomers[[#This Row],[IncomeRange]]<75000,"Mid","High")),"N/A") -> High | P14: =IFERROR(TEXT(tblCustomers[[#This Row],[JoinDate]],"DDDD"),"") -> Thursday | Q14: =IFERROR(IF(WEEKDAY(tblCustomers[[#This Row],[JoinDate]],2)>=6,TRUE(),FALSE()),FALSE()) -> FALSE | R14: =IFERROR(DATEDIF(tblCustomers[[#This Row],[JoinDate]],TODAY(),"M"),0) -> 24 | S14: =IFERROR(IF(AND(tblCustomers[[#This Row],[Age]]>=18,tblCustomers[[#This Row],[IncomeRange]]>0,tblCustomers[[#This Row],[CustomerID]]<>""),"OK","CHECK"),"CHECK") -> OK
... A202: =IFERROR(TRIM(tblCustomers[[#This Row],[CustomerID]]),"") -> C0200 | B202: =IFERROR(PROPER(TRIM(tblCustomers[[#This Row],[Name]])),"") -> Manoj Pillai | C202: =IFERROR(PROPER(TRIM(tblCustomers[[#This Row],[Gender]])),"") -> Male | D202: =IFERROR(tblCustomers[[#This Row],[Age]],"") -> 35 | E202: =IFERROR(PROPER(TRIM(tblCustomers[[#This Row],[City/Region]])),"") -> Lucknow | F202: =IFERROR(tblCustomers[[#This Row],[IncomeRange]],"") -> 73373 | G202: =IFERROR(PROPER(TRIM(tblCustomers[[#This Row],[Occupation]])),"") -> Consultant | H202: =IFERROR(tblCustomers[[#This Row],[JoinDate]],"") -> 45578 | I202: =IFERROR(PROPER(TRIM(tblCustomers[[#This Row],[PurchaseChannel]])),"") -> Offline | J202: =IFERROR(PROPER(TRIM(tblCustomers[[#This Row],[CustomerType]])),"") -> Returning | K202: =IFERROR(PROPER(TRIM(tblCustomers[[#This Row],[EngagementLevel]])),"") -> Medium | L202: =IFERROR(PROPER(TRIM(tblCustomers[[#This Row],[DiscountSensitivity]])),"") -> Low | M202: =IFERROR(tblCustomers[[#This Row],[LastPurchaseDate]],"") -> 45751 | N202: =IFERROR(IF(tblCustomers[[#This Row],[Age]]<25,"<25",IF(tblCustomers[[#This Row],[Age]]<40,"25-39",IF(tblCustomers[[#This Row],[Age]]<55,"40-54","55+"))),"N/A") -> 25-39 | O202: =IFERROR(IF(tblCustomers[[#This Row],[IncomeRange]]<25000,"Low",IF(tblCustomers[[#This Row],[IncomeRange]]<75000,"Mid","High")),"N/A") -> Mid | P202: =IFERROR(TEXT(tblCustomers[[#This Row],[JoinDate]],"DDDD"),"") -> Sunday | Q202: =IFERROR(IF(WEEKDAY(tblCustomers[[#This Row],[JoinDate]],2)>=6,TRUE(),FALSE()),FALSE()) -> TRUE | R202: =IFERROR(DATEDIF(tblCustomers[[#This Row],[JoinDate]],TODAY(),"M"),0) -> 18 | S202: =IFERROR(IF(AND(tblCustomers[[#This Row],[Age]]>=18,tblCustomers[[#This Row],[IncomeRange]]>0,tblCustomers[[#This Row],[CustomerID]]<>""),"OK","CHECK"),"CHECK") -> OK

Sheet Segmentation Logic
A1: 🔍 tblRFM — RFM Analysis + Survey Merge + Segment Assignment (Formula-Driven)
A2: CustomerID | B2: Name | C2: City/Region | D2: CustomerType | E2: EngagementLevel | F2: RFM_Recency | G2: RFM_Frequency | H2: RFM_Monetary | I2: R_Score | J2: F_Score | K2: M_Score | L2: RFM_Score | M2: Satisfaction | N2: RecommendationLikelihood | O2: SatisfactionIndex | P2: AgeGroup | Q2: IncomeBracket | R2: EngagementFlag | S2: ValueFlag | T2: CustomerSegment | U2: ProductPreference
A3: =IFERROR(tblClean[[#This Row],[CustomerID]],"") -> C0001 | B3: =IFERROR(tblClean[[#This Row],[Name (Cleaned)]],"") -> Arjun Sharma | C3: =IFERROR(tblClean[[#This Row],[City/Region (Cleaned)]],"") -> Noida | D3: =IFERROR(tblClean[[#This Row],[CustomerType]],"") -> New | E3: =IFERROR(tblClean[[#This Row],[EngagementLevel]],"") -> Low | F3: =IFERROR(TODAY()-'Raw Data'!M3,999) -> 40 | G3: =IFERROR(COUNTIFS(tblTransactions[CustomerID],A3),0) -> 1 | H3: =IFERROR(SUMIFS(tblTransactions[Amount (INR)],tblTransactions[CustomerID],A3),0) -> 10900 | I3: =IFERROR(IF(F3<=30,5,IF(F3<=60,4,IF(F3<=90,3,IF(F3<=180,2,1)))),1) -> 4 | J3: =IFERROR(IF(G3>=8,5,IF(G3>=6,4,IF(G3>=4,3,IF(G3>=2,2,1)))),1) -> 1 | K3: =IFERROR(IF(H3>=50000,5,IF(H3>=30000,4,IF(H3>=15000,3,IF(H3>=5000,2,1)))),1) -> 2 | L3: =IFERROR(TEXT(I3,"0")&TEXT(J3,"0")&TEXT(K3,"0"),"") -> 412 | M3: =IFERROR(INDEX('Raw Data'!$X$3:$X$202,MATCH(A3,'Raw Data'!$W$3:$W$202,0)),"") -> 4 | N3: =IFERROR(INDEX('Raw Data'!$Z$3:$Z$202,MATCH(A3,'Raw Data'!$W$3:$W$202,0)),"") -> 8 | O3: =IFERROR((IF(ISNUMBER(M3),M3,0)+IF(ISNUMBER(N3),N3/2,0))/MAX(1,(IF(ISNUMBER(M3),1,0)+IF(ISNUMBER(N3),1,0))),"") -> 4 | P3: =IFERROR(tblClean[[#This Row],[AgeGroup]],"") -> 55+ | Q3: =IFERROR(tblClean[[#This Row],[IncomeBracket]],"") -> Low | R3: =IFERROR(IF(E3="Low","LOW",IF(E3="Medium","MED","HIGH")),"N/A") -> LOW | S3: =IFERROR(IF(H3>=50000,"Premium",IF(H3>=15000,"Standard","Budget")),"N/A") -> Budget | T3: =IFERROR(IF(L3="555","Loyal",IF(AND(ISNUMBER(O3),O3>=4.5,G3>=3),"Loyal",IF(H3>=50000,"High Value",IF(AND(F3>90,G3<3),"At Risk",IF(AND(H3<30000,G3>=5),"Bargain Seeker","General"))))),"General") -> General | U3: =IFERROR(INDEX(tblTransactions[ProductCategory],MATCH(A3,tblTransactions[CustomerID],0)),"N/A") -> Beauty
A4: =IFERROR(tblClean[[#This Row],[CustomerID]],"") -> C0002 | B4: =IFERROR(tblClean[[#This Row],[Name (Cleaned)]],"") -> Vikram Singh | C4: =IFERROR(tblClean[[#This Row],[City/Region (Cleaned)]],"") -> Bangalore | D4: =IFERROR(tblClean[[#This Row],[CustomerType]],"") -> New | E4: =IFERROR(tblClean[[#This Row],[EngagementLevel]],"") -> Medium | F4: =IFERROR(TODAY()-'Raw Data'!M4,999) -> 82 | G4: =IFERROR(COUNTIFS(tblTransactions[CustomerID],A4),0) -> 1 | H4: =IFERROR(SUMIFS(tblTransactions[Amount (INR)],tblTransactions[CustomerID],A4),0) -> 3780 | I4: =IFERROR(IF(F4<=30,5,IF(F4<=60,4,IF(F4<=90,3,IF(F4<=180,2,1)))),1) -> 3 | J4: =IFERROR(IF(G4>=8,5,IF(G4>=6,4,IF(G4>=4,3,IF(G4>=2,2,1)))),1) -> 1 | K4: =IFERROR(IF(H4>=50000,5,IF(H4>=30000,4,IF(H4>=15000,3,IF(H4>=5000,2,1)))),1) -> 1 | L4: =IFERROR(TEXT(I4,"0")&TEXT(J4,"0")&TEXT(K4,"0"),"") -> 311 | M4: =IFERROR(INDEX('Raw Data'!$X$3:$X$202,MATCH(A4,'Raw Data'!$W$3:$W$202,0)),"") -> 3 | N4: =IFERROR(INDEX('Raw Data'!$Z$3:$Z$202,MATCH(A4,'Raw Data'!$W$3:$W$202,0)),"") -> 6 | O4: =IFERROR((IF(ISNUMBER(M4),M4,0)+IF(ISNUMBER(N4),N4/2,0))/MAX(1,(IF(ISNUMBER(M4),1,0)+IF(ISNUMBER(N4),1,0))),"") -> 3 | P4: =IFERROR(tblClean[[#This Row],[AgeGroup]],"") -> 40-54 | Q4: =IFERROR(tblClean[[#This Row],[IncomeBracket]],"") -> High | R4: =IFERROR(IF(E4="Low","LOW",IF(E4="Medium","MED","HIGH")),"N/A") -> MED | S4: =IFERROR(IF(H4>=50000,"Premium",IF(H4>=15000,"Standard","Budget")),"N/A") -> Budget | T4: =IFERROR(IF(L4="555","Loyal",IF(AND(ISNUMBER(O4),O4>=4.5,G4>=3),"Loyal",IF(H4>=50000,"High Value",IF(AND(F4>90,G4<3),"At Risk",IF(AND(H4<30000,G4>=5),"Bargain Seeker","General"))))),"General") -> General | U4: =IFERROR(INDEX(tblTransactions[ProductCategory],MATCH(A4,tblTransactions[CustomerID],0)),"N/A") -> Grocery
A5: =IFERROR(tblClean[[#This Row],[CustomerID]],"") -> C0003 | B5: =IFERROR(tblClean[[#This Row],[Name (Cleaned)]],"") -> Rohan Mehta | C5: =IFERROR(tblClean[[#This Row],[City/Region (Cleaned)]],"") -> Indore | D5: =IFERROR(tblClean[[#This Row],[CustomerType]],"") -> Returning | E5: =IFERROR(tblClean[[#This Row],[EngagementLevel]],"") -> Low | F5: =IFERROR(TODAY()-'Raw Data'!M5,999) -> 172 | G5: =IFERROR(COUNTIFS(tblTransactions[CustomerID],A5),0) -> 2 | H5: =IFERROR(SUMIFS(tblTransactions[Amount (INR)],tblTransactions[CustomerID],A5),0) -> 5380 | I5: =IFERROR(IF(F5<=30,5,IF(F5<=60,4,IF(F5<=90,3,IF(F5<=180,2,1)))),1) -> 2 | J5: =IFERROR(IF(G5>=8,5,IF(G5>=6,4,IF(G5>=4,3,IF(G5>=2,2,1)))),1) -> 2 | K5: =IFERROR(IF(H5>=50000,5,IF(H5>=30000,4,IF(H5>=15000,3,IF(H5>=5000,2,1)))),1) -> 2 | L5: =IFERROR(TEXT(I5,"0")&TEXT(J5,"0")&TEXT(K5,"0"),"") -> 222 | M5: =IFERROR(INDEX('Raw Data'!$X$3:$X$202,MATCH(A5,'Raw Data'!$W$3:$W$202,0)),"") -> 4 | N5: =IFERROR(INDEX('Raw Data'!$Z$3:$Z$202,MATCH(A5,'Raw Data'!$W$3:$W$202,0)),"") -> 7 | O5: =IFERROR((IF(ISNUMBER(M5),M5,0)+IF(ISNUMBER(N5),N5/2,0))/MAX(1,(IF(ISNUMBER(M5),1,0)+IF(ISNUMBER(N5),1,0))),"") -> 3.75 | P5: =IFERROR(tblClean[[#This Row],[AgeGroup]],"") -> 25-39 | Q5: =IFERROR(tblClean[[#This Row],[IncomeBracket]],"") -> Mid | R5: =IFERROR(IF(E5="Low","LOW",IF(E5="Medium","MED","HIGH")),"N/A") -> LOW | S5: =IFERROR(IF(H5>=50000,"Premium",IF(H5>=15000,"Standard","Budget")),"N/A") -> Budget | T5: =IFERROR(IF(L5="555","Loyal",IF(AND(ISNUMBER(O5),O5>=4.5,G5>=3),"Loyal",IF(H5>=50000,"High Value",IF(AND(F5>90,G5<3),"At Risk",IF(AND(H5<30000,G5>=5),"Bargain Seeker","General"))))),"General") -> At Risk | U5: =IFERROR(INDEX(tblTransactions[ProductCategory],MATCH(A5,tblTransactions[CustomerID],0)),"N/A") -> Grocery
A6: =IFERROR(tblClean[[#This Row],[CustomerID]],"") -> C0004 | B6: =IFERROR(tblClean[[#This Row],[Name (Cleaned)]],"") -> Nikhil Gupta | C6: =IFERROR(tblClean[[#This Row],[City/Region (Cleaned)]],"") -> Jaipur | D6: =IFERROR(tblClean[[#This Row],[CustomerType]],"") -> New | E6: =IFERROR(tblClean[[#This Row],[EngagementLevel]],"") -> Low | F6: =IFERROR(TODAY()-'Raw Data'!M6,999) -> 51 | G6: =IFERROR(COUNTIFS(tblTransactions[CustomerID],A6),0) -> 1 | H6: =IFERROR(SUMIFS(tblTransactions[Amount (INR)],tblTransactions[CustomerID],A6),0) -> 12070 | I6: =IFERROR(IF(F6<=30,5,IF(F6<=60,4,IF(F6<=90,3,IF(F6<=180,2,1)))),1) -> 4 | J6: =IFERROR(IF(G6>=8,5,IF(G6>=6,4,IF(G6>=4,3,IF(G6>=2,2,1)))),1) -> 1 | K6: =IFERROR(IF(H6>=50000,5,IF(H6>=30000,4,IF(H6>=15000,3,IF(H6>=5000,2,1)))),1) -> 2 | L6: =IFERROR(TEXT(I6,"0")&TEXT(J6,"0")&TEXT(K6,"0"),"") -> 412 | M6: =IFERROR(INDEX('Raw Data'!$X$3:$X$202,MATCH(A6,'Raw Data'!$W$3:$W$202,0)),"") -> 3 | N6: =IFERROR(INDEX('Raw Data'!$Z$3:$Z$202,MATCH(A6,'Raw Data'!$W$3:$W$202,0)),"") -> 6 | O6: =IFERROR((IF(ISNUMBER(M6),M6,0)+IF(ISNUMBER(N6),N6/2,0))/MAX(1,(IF(ISNUMBER(M6),1,0)+IF(ISNUMBER(N6),1,0))),"") -> 3 | P6: =IFERROR(tblClean[[#This Row],[AgeGroup]],"") -> 40-54 | Q6: =IFERROR(tblClean[[#This Row],[IncomeBracket]],"") -> Mid | R6: =IFERROR(IF(E6="Low","LOW",IF(E6="Medium","MED","HIGH")),"N/A") -> LOW | S6: =IFERROR(IF(H6>=50000,"Premium",IF(H6>=15000,"Standard","Budget")),"N/A") -> Budget | T6: =IFERROR(IF(L6="555","Loyal",IF(AND(ISNUMBER(O6),O6>=4.5,G6>=3),"Loyal",IF(H6>=50000,"High Value",IF(AND(F6>90,G6<3),"At Risk",IF(AND(H6<30000,G6>=5),"Bargain Seeker","General"))))),"General") -> General | U6: =IFERROR(INDEX(tblTransactions[ProductCategory],MATCH(A6,tblTransactions[CustomerID],0)),"N/A") -> Electronics
A7: =IFERROR(tblClean[[#This Row],[CustomerID]],"") -> C0005 | B7: =IFERROR(tblClean[[#This Row],[Name (Cleaned)]],"") -> Amit Verma | C7: =IFERROR(tblClean[[#This Row],[City/Region (Cleaned)]],"") -> Bhubaneswar | D7: =IFERROR(tblClean[[#This Row],[CustomerType]],"") -> Returning | E7: =IFERROR(tblClean[[#This Row],[EngagementLevel]],"") -> High | F7: =IFERROR(TODAY()-'Raw Data'!M7,999) -> 112 | G7: =IFERROR(COUNTIFS(tblTransactions[CustomerID],A7),0) -> 14 | H7: =IFERROR(SUMIFS(tblTransactions[Amount (INR)],tblTransactions[CustomerID],A7),0) -> 66820 | I7: =IFERROR(IF(F7<=30,5,IF(F7<=60,4,IF(F7<=90,3,IF(F7<=180,2,1)))),1) -> 2 | J7: =IFERROR(IF(G7>=8,5,IF(G7>=6,4,IF(G7>=4,3,IF(G7>=2,2,1)))),1) -> 5 | K7: =IFERROR(IF(H7>=50000,5,IF(H7>=30000,4,IF(H7>=15000,3,IF(H7>=5000,2,1)))),1) -> 5 | L7: =IFERROR(TEXT(I7,"0")&TEXT(J7,"0")&TEXT(K7,"0"),"") -> 255 | M7: =IFERROR(INDEX('Raw Data'!$X$3:$X$202,MATCH(A7,'Raw Data'!$W$3:$W$202,0)),"") -> 4 | N7: =IFERROR(INDEX('Raw Data'!$Z$3:$Z$202,MATCH(A7,'Raw Data'!$W$3:$W$202,0)),"") -> 4 | O7: =IFERROR((IF(ISNUMBER(M7),M7,0)+IF(ISNUMBER(N7),N7/2,0))/MAX(1,(IF(ISNUMBER(M7),1,0)+IF(ISNUMBER(N7),1,0))),"") -> 3 | P7: =IFERROR(tblClean[[#This Row],[AgeGroup]],"") -> 40-54 | Q7: =IFERROR(tblClean[[#This Row],[IncomeBracket]],"") -> Mid | R7: =IFERROR(IF(E7="Low","LOW",IF(E7="Medium","MED","HIGH")),"N/A") -> HIGH | S7: =IFERROR(IF(H7>=50000,"Premium",IF(H7>=15000,"Standard","Budget")),"N/A") -> Premium | T7: =IFERROR(IF(L7="555","Loyal",IF(AND(ISNUMBER(O7),O7>=4.5,G7>=3),"Loyal",IF(H7>=50000,"High Value",IF(AND(F7>90,G7<3),"At Risk",IF(AND(H7<30000,G7>=5),"Bargain Seeker","General"))))),"General") -> High Value | U7: =IFERROR(INDEX(tblTransactions[ProductCategory],MATCH(A7,tblTransactions[CustomerID],0)),"N/A") -> Home Decor
A8: =IFERROR(tblClean[[#This Row],[CustomerID]],"") -> C0006 | B8: =IFERROR(tblClean[[#This Row],[Name (Cleaned)]],"") -> Suresh Kumar | C8: =IFERROR(tblClean[[#This Row],[City/Region (Cleaned)]],"") -> Kolkata | D8: =IFERROR(tblClean[[#This Row],[CustomerType]],"") -> Returning | E8: =IFERROR(tblClean[[#This Row],[EngagementLevel]],"") -> Low | F8: =IFERROR(TODAY()-'Raw Data'!M8,999) -> 165 | G8: =IFERROR(COUNTIFS(tblTransactions[CustomerID],A8),0) -> 1 | H8: =IFERROR(SUMIFS(tblTransactions[Amount (INR)],tblTransactions[CustomerID],A8),0) -> 12330 | I8: =IFERROR(IF(F8<=30,5,IF(F8<=60,4,IF(F8<=90,3,IF(F8<=180,2,1)))),1) -> 2 | J8: =IFERROR(IF(G8>=8,5,IF(G8>=6,4,IF(G8>=4,3,IF(G8>=2,2,1)))),1) -> 1 | K8: =IFERROR(IF(H8>=50000,5,IF(H8>=30000,4,IF(H8>=15000,3,IF(H8>=5000,2,1)))),1) -> 2 | L8: =IFERROR(TEXT(I8,"0")&TEXT(J8,"0")&TEXT(K8,"0"),"") -> 212 | M8: =IFERROR(INDEX('Raw Data'!$X$3:$X$202,MATCH(A8,'Raw Data'!$W$3:$W$202,0)),"") -> 4 | N8: =IFERROR(INDEX('Raw Data'!$Z$3:$Z$202,MATCH(A8,'Raw Data'!$W$3:$W$202,0)),"") -> 7 | O8: =IFERROR((IF(ISNUMBER(M8),M8,0)+IF(ISNUMBER(N8),N8/2,0))/MAX(1,(IF(ISNUMBER(M8),1,0)+IF(ISNUMBER(N8),1,0))),"") -> 3.75 | P8: =IFERROR(tblClean[[#This Row],[AgeGroup]],"") -> 40-54 | Q8: =IFERROR(tblClean[[#This Row],[IncomeBracket]],"") -> High | R8: =IFERROR(IF(E8="Low","LOW",IF(E8="Medium","MED","HIGH")),"N/A") -> LOW | S8: =IFERROR(IF(H8>=50000,"Premium",IF(H8>=15000,"Standard","Budget")),"N/A") -> Budget | T8: =IFERROR(IF(L8="555","Loyal",IF(AND(ISNUMBER(O8),O8>=4.5,G8>=3),"Loyal",IF(H8>=50000,"High Value",IF(AND(F8>90,G8<3),"At Risk",IF(AND(H8<30000,G8>=5),"Bargain Seeker","General"))))),"General") -> At Risk | U8: =IFERROR(INDEX(tblTransactions[ProductCategory],MATCH(A8,tblTransactions[CustomerID],0)),"N/A") -> Grocery
A9: =IFERROR(tblClean[[#This Row],[CustomerID]],"") -> C0007 | B9: =IFERROR(tblClean[[#This Row],[Name (Cleaned)]],"") -> Rajesh Patel | C9: =IFERROR(tblClean[[#This Row],[City/Region (Cleaned)]],"") -> Bangalore | D9: =IFERROR(tblClean[[#This Row],[CustomerType]],"") -> Returning | E9: =IFERROR(tblClean[[#This Row],[EngagementLevel]],"") -> High | F9: =IFERROR(TODAY()-'Raw Data'!M9,999) -> 225 | G9: =IFERROR(COUNTIFS(tblTransactions[CustomerID],A9),0) -> 14 | H9: =IFERROR(SUMIFS(tblTransactions[Amount (INR)],tblTransactions[CustomerID],A9),0) -> 108600 | I9: =IFERROR(IF(F9<=30,5,IF(F9<=60,4,IF(F9<=90,3,IF(F9<=180,2,1)))),1) -> 1 | J9: =IFERROR(IF(G9>=8,5,IF(G9>=6,4,IF(G9>=4,3,IF(G9>=2,2,1)))),1) -> 5 | K9: =IFERROR(IF(H9>=50000,5,IF(H9>=30000,4,IF(H9>=15000,3,IF(H9>=5000,2,1)))),1) -> 5 | L9: =IFERROR(TEXT(I9,"0")&TEXT(J9,"0")&TEXT(K9,"0"),"") -> 155 | M9: =IFERROR(INDEX('Raw Data'!$X$3:$X$202,MATCH(A9,'Raw Data'!$W$3:$W$202,0)),"") -> 4 | N9: =IFERROR(INDEX('Raw Data'!$Z$3:$Z$202,MATCH(A9,'Raw Data'!$W$3:$W$202,0)),"") -> 4 | O9: =IFERROR((IF(ISNUMBER(M9),M9,0)+IF(ISNUMBER(N9),N9/2,0))/MAX(1,(IF(ISNUMBER(M9),1,0)+IF(ISNUMBER(N9),1,0))),"") -> 3 | P9: =IFERROR(tblClean[[#This Row],[AgeGroup]],"") -> 25-39 | Q9: =IFERROR(tblClean[[#This Row],[IncomeBracket]],"") -> High | R9: =IFERROR(IF(E9="Low","LOW",IF(E9="Medium","MED","HIGH")),"N/A") -> HIGH | S9: =IFERROR(IF(H9>=50000,"Premium",IF(H9>=15000,"Standard","Budget")),"N/A") -> Premium | T9: =IFERROR(IF(L9="555","Loyal",IF(AND(ISNUMBER(O9),O9>=4.5,G9>=3),"Loyal",IF(H9>=50000,"High Value",IF(AND(F9>90,G9<3),"At Risk",IF(AND(H9<30000,G9>=5),"Bargain Seeker","General"))))),"General") -> High Value | U9: =IFERROR(INDEX(tblTransactions[ProductCategory],MATCH(A9,tblTransactions[CustomerID],0)),"N/A") -> Clothing
A10: =IFERROR(tblClean[[#This Row],[CustomerID]],"") -> C0008 | B10: =IFERROR(tblClean[[#This Row],[Name (Cleaned)]],"") -> Aditya Joshi | C10: =IFERROR(tblClean[[#This Row],[City/Region (Cleaned)]],"") -> Hyderabad | D10: =IFERROR(tblClean[[#This Row],[CustomerType]],"") -> New | E10: =IFERROR(tblClean[[#This Row],[EngagementLevel]],"") -> Medium | F10: =IFERROR(TODAY()-'Raw Data'!M10,999) -> 93 | G10: =IFERROR(COUNTIFS(tblTransactions[CustomerID],A10),0) -> 1 | H10: =IFERROR(SUMIFS(tblTransactions[Amount (INR)],tblTransactions[CustomerID],A10),0) -> 570 | I10: =IFERROR(IF(F10<=30,5,IF(F10<=60,4,IF(F10<=90,3,IF(F10<=180,2,1)))),1) -> 2 | J10: =IFERROR(IF(G10>=8,5,IF(G10>=6,4,IF(G10>=4,3,IF(G10>=2,2,1)))),1) -> 1 | K10: =IFERROR(IF(H10>=50000,5,IF(H10>=30000,4,IF(H10>=15000,3,IF(H10>=5000,2,1)))),1) -> 1 | L10: =IFERROR(TEXT(I10,"0")&TEXT(J10,"0")&TEXT(K10,"0"),"") -> 211 | M10: =IFERROR(INDEX('Raw Data'!$X$3:$X$202,MATCH(A10,'Raw Data'!$W$3:$W$202,0)),"") -> 1 | N10: =IFERROR(INDEX('Raw Data'!$Z$3:$Z$202,MATCH(A10,'Raw Data'!$W$3:$W$202,0)),"") -> 5 | O10: =IFERROR((IF(ISNUMBER(M10),M10,0)+IF(ISNUMBER(N10),N10/2,0))/MAX(1,(IF(ISNUMBER(M10),1,0)+IF(ISNUMBER(N10),1,0))),"") -> 1.75 | P10: =IFERROR(tblClean[[#This Row],[AgeGroup]],"") -> 40-54 | Q10: =IFERROR(tblClean[[#This Row],[IncomeBracket]],"") -> High | R10: =IFERROR(IF(E10="Low","LOW",IF(E10="Medium","MED","HIGH")),"N/A") -> MED | S10: =IFERROR(IF(H10>=50000,"Premium",IF(H10>=15000,"Standard","Budget")),"N/A") -> Budget | T10: =IFERROR(IF(L10="555","Loyal",IF(AND(ISNUMBER(O10),O10>=4.5,G10>=3),"Loyal",IF(H10>=50000,"High Value",IF(AND(F10>90,G10<3),"At Risk",IF(AND(H10<30000,G10>=5),"Bargain Seeker","General"))))),"General") -> At Risk | U10: =IFERROR(INDEX(tblTransactions[ProductCategory],MATCH(A10,tblTransactions[CustomerID],0)),"N/A") -> Grocery
A11: =IFERROR(tblClean[[#This Row],[CustomerID]],"") -> C0009 | B11: =IFERROR(tblClean[[#This Row],[Name (Cleaned)]],"") -> Karan Kapoor | C11: =IFERROR(tblClean[[#This Row],[City/Region (Cleaned)]],"") -> Ahmedabad | D11: =IFERROR(tblClean[[#This Row],[CustomerType]],"") -> New | E11: =IFERROR(tblClean[[#This Row],[EngagementLevel]],"") -> High | F11: =IFERROR(TODAY()-'Raw Data'!M11,999) -> 92 | G11: =IFERROR(COUNTIFS(tblTransactions[CustomerID],A11),0) -> 1 | H11: =IFERROR(SUMIFS(tblTransactions[Amount (INR)],tblTransactions[CustomerID],A11),0) -> 6730 | I11: =IFERROR(IF(F11<=30,5,IF(F11<=60,4,IF(F11<=90,3,IF(F11<=180,2,1)))),1) -> 2 | J11: =IFERROR(IF(G11>=8,5,IF(G11>=6,4,IF(G11>=4,3,IF(G11>=2,2,1)))),1) -> 1 | K11: =IFERROR(IF(H11>=50000,5,IF(H11>=30000,4,IF(H11>=15000,3,IF(H11>=5000,2,1)))),1) -> 2 | L11: =IFERROR(TEXT(I11,"0")&TEXT(J11,"0")&TEXT(K11,"0"),"") -> 212 | M11: =IFERROR(INDEX('Raw Data'!$X$3:$X$202,MATCH(A11,'Raw Data'!$W$3:$W$202,0)),"") -> 4 | N11: =IFERROR(INDEX('Raw Data'!$Z$3:$Z$202,MATCH(A11,'Raw Data'!$W$3:$W$202,0)),"") -> 9 | O11: =IFERROR((IF(ISNUMBER(M11),M11,0)+IF(ISNUMBER(N11),N11/2,0))/MAX(1,(IF(ISNUMBER(M11),1,0)+IF(ISNUMBER(N11),1,0))),"") -> 4.25 | P11: =IFERROR(tblClean[[#This Row],[AgeGroup]],"") -> 40-54 | Q11: =IFERROR(tblClean[[#This Row],[IncomeBracket]],"") -> High | R11: =IFERROR(IF(E11="Low","LOW",IF(E11="Medium","MED","HIGH")),"N/A") -> HIGH | S11: =IFERROR(IF(H11>=50000,"Premium",IF(H11>=15000,"Standard","Budget")),"N/A") -> Budget | T11: =IFERROR(IF(L11="555","Loyal",IF(AND(ISNUMBER(O11),O11>=4.5,G11>=3),"Loyal",IF(H11>=50000,"High Value",IF(AND(F11>90,G11<3),"At Risk",IF(AND(H11<30000,G11>=5),"Bargain Seeker","General"))))),"General") -> At Risk | U11: =IFERROR(INDEX(tblTransactions[ProductCategory],MATCH(A11,tblTransactions[CustomerID],0)),"N/A") -> Grocery
A12: =IFERROR(tblClean[[#This Row],[CustomerID]],"") -> C0010 | B12: =IFERROR(tblClean[[#This Row],[Name (Cleaned)]],"") -> Deepak Nair | C12: =IFERROR(tblClean[[#This Row],[City/Region (Cleaned)]],"") -> Jaipur | D12: =IFERROR(tblClean[[#This Row],[CustomerType]],"") -> Returning | E12: =IFERROR(tblClean[[#This Row],[EngagementLevel]],"") -> High | F12: =IFERROR(TODAY()-'Raw Data'!M12,999) -> 40 | G12: =IFERROR(COUNTIFS(tblTransactions[CustomerID],A12),0) -> 14 | H12: =IFERROR(SUMIFS(tblTransactions[Amount (INR)],tblTransactions[CustomerID],A12),0) -> 51230 | I12: =IFERROR(IF(F12<=30,5,IF(F12<=60,4,IF(F12<=90,3,IF(F12<=180,2,1)))),1) -> 4 | J12: =IFERROR(IF(G12>=8,5,IF(G12>=6,4,IF(G12>=4,3,IF(G12>=2,2,1)))),1) -> 5 | K12: =IFERROR(IF(H12>=50000,5,IF(H12>=30000,4,IF(H12>=15000,3,IF(H12>=5000,2,1)))),1) -> 5 | L12: =IFERROR(TEXT(I12,"0")&TEXT(J12,"0")&TEXT(K12,"0"),"") -> 455 | M12: =IFERROR(INDEX('Raw Data'!$X$3:$X$202,MATCH(A12,'Raw Data'!$W$3:$W$202,0)),"") -> 3 | N12: =IFERROR(INDEX('Raw Data'!$Z$3:$Z$202,MATCH(A12,'Raw Data'!$W$3:$W$202,0)),"") -> 6 | O12: =IFERROR((IF(ISNUMBER(M12),M12,0)+IF(ISNUMBER(N12),N12/2,0))/MAX(1,(IF(ISNUMBER(M12),1,0)+IF(ISNUMBER(N12),1,0))),"") -> 3 | P12: =IFERROR(tblClean[[#This Row],[AgeGroup]],"") -> <25 | Q12: =IFERROR(tblClean[[#This Row],[IncomeBracket]],"") -> Mid | R12: =IFERROR(IF(E12="Low","LOW",IF(E12="Medium","MED","HIGH")),"N/A") -> HIGH | S12: =IFERROR(IF(H12>=50000,"Premium",IF(H12>=15000,"Standard","Budget")),"N/A") -> Premium | T12: =IFERROR(IF(L12="555","Loyal",IF(AND(ISNUMBER(O12),O12>=4.5,G12>=3),"Loyal",IF(H12>=50000,"High Value",IF(AND(F12>90,G12<3),"At Risk",IF(AND(H12<30000,G12>=5),"Bargain Seeker","General"))))),"General") -> High Value | U12: =IFERROR(INDEX(tblTransactions[ProductCategory],MATCH(A12,tblTransactions[CustomerID],0)),"N/A") -> Sports
A13: =IFERROR(tblClean[[#This Row],[CustomerID]],"") -> C0011 | B13: =IFERROR(tblClean[[#This Row],[Name (Cleaned)]],"") -> Manish Tiwari | C13: =IFERROR(tblClean[[#This Row],[City/Region (Cleaned)]],"") -> Bhopal | D13: =IFERROR(tblClean[[#This Row],[CustomerType]],"") -> New | E13: =IFERROR(tblClean[[#This Row],[EngagementLevel]],"") -> Medium | F13: =IFERROR(TODAY()-'Raw Data'!M13,999) -> 66 | G13: =IFERROR(COUNTIFS(tblTransactions[CustomerID],A13),0) -> 1 | H13: =IFERROR(SUMIFS(tblTransactions[Amount (INR)],tblTransactions[CustomerID],A13),0) -> 3660 | I13: =IFERROR(IF(F13<=30,5,IF(F13<=60,4,IF(F13<=90,3,IF(F13<=180,2,1)))),1) -> 3 | J13: =IFERROR(IF(G13>=8,5,IF(G13>=6,4,IF(G13>=4,3,IF(G13>=2,2,1)))),1) -> 1 | K13: =IFERROR(IF(H13>=50000,5,IF(H13>=30000,4,IF(H13>=15000,3,IF(H13>=5000,2,1)))),1) -> 1 | L13: =IFERROR(TEXT(I13,"0")&TEXT(J13,"0")&TEXT(K13,"0"),"") -> 311 | M13: =IFERROR(INDEX('Raw Data'!$X$3:$X$202,MATCH(A13,'Raw Data'!$W$3:$W$202,0)),"") -> 4 | N13: =IFERROR(INDEX('Raw Data'!$Z$3:$Z$202,MATCH(A13,'Raw Data'!$W$3:$W$202,0)),"") -> 8 | O13: =IFERROR((IF(ISNUMBER(M13),M13,0)+IF(ISNUMBER(N13),N13/2,0))/MAX(1,(IF(ISNUMBER(M13),1,0)+IF(ISNUMBER(N13),1,0))),"") -> 4 | P13: =IFERROR(tblClean[[#This Row],[AgeGroup]],"") -> 55+ | Q13: =IFERROR(tblClean[[#This Row],[IncomeBracket]],"") -> Mid | R13: =IFERROR(IF(E13="Low","LOW",IF(E13="Medium","MED","HIGH")),"N/A") -> MED | S13: =IFERROR(IF(H13>=50000,"Premium",IF(H13>=15000,"Standard","Budget")),"N/A") -> Budget | T13: =IFERROR(IF(L13="555","Loyal",IF(AND(ISNUMBER(O13),O13>=4.5,G13>=3),"Loyal",IF(H13>=50000,"High Value",IF(AND(F13>90,G13<3),"At Risk",IF(AND(H13<30000,G13>=5),"Bargain Seeker","General"))))),"General") -> General | U13: =IFERROR(INDEX(tblTransactions[ProductCategory],MATCH(A13,tblTransactions[CustomerID],0)),"N/A") -> Beauty
A14: =IFERROR(tblClean[[#This Row],[CustomerID]],"") -> C0012 | B14: =IFERROR(tblClean[[#This Row],[Name (Cleaned)]],"") -> Gaurav Saxena | C14: =IFERROR(tblClean[[#This Row],[City/Region (Cleaned)]],"") -> Lucknow | D14: =IFERROR(tblClean[[#This Row],[CustomerType]],"") -> Returning | E14: =IFERROR(tblClean[[#This Row],[EngagementLevel]],"") -> Low | F14: =IFERROR(TODAY()-'Raw Data'!M14,999) -> 160 | G14: =IFERROR(COUNTIFS(tblTransactions[CustomerID],A14),0) -> 2 | H14: =IFERROR(SUMIFS(tblTransactions[Amount (INR)],tblTransactions[CustomerID],A14),0) -> 5290 | I14: =IFERROR(IF(F14<=30,5,IF(F14<=60,4,IF(F14<=90,3,IF(F14<=180,2,1)))),1) -> 2 | J14: =IFERROR(IF(G14>=8,5,IF(G14>=6,4,IF(G14>=4,3,IF(G14>=2,2,1)))),1) -> 2 | K14: =IFERROR(IF(H14>=50000,5,IF(H14>=30000,4,IF(H14>=15000,3,IF(H14>=5000,2,1)))),1) -> 2 | L14: =IFERROR(TEXT(I14,"0")&TEXT(J14,"0")&TEXT(K14,"0"),"") -> 222 | M14: =IFERROR(INDEX('Raw Data'!$X$3:$X$202,MATCH(A14,'Raw Data'!$W$3:$W$202,0)),"") -> 4 | N14: =IFERROR(INDEX('Raw Data'!$Z$3:$Z$202,MATCH(A14,'Raw Data'!$W$3:$W$202,0)),"") -> 8 | O14: =IFERROR((IF(ISNUMBER(M14),M14,0)+IF(ISNUMBER(N14),N14/2,0))/MAX(1,(IF(ISNUMBER(M14),1,0)+IF(ISNUMBER(N14),1,0))),"") -> 4 | P14: =IFERROR(tblClean[[#This Row],[AgeGroup]],"") -> 55+ | Q14: =IFERROR(tblClean[[#This Row],[IncomeBracket]],"") -> High | R14: =IFERROR(IF(E14="Low","LOW",IF(E14="Medium","MED","HIGH")),"N/A") -> LOW | S14: =IFERROR(IF(H14>=50000,"Premium",IF(H14>=15000,"Standard","Budget")),"N/A") -> Budget | T14: =IFERROR(IF(L14="555","Loyal",IF(AND(ISNUMBER(O14),O14>=4.5,G14>=3),"Loyal",IF(H14>=50000,"High Value",IF(AND(F14>90,G14<3),"At Risk",IF(AND(H14<30000,G14>=5),"Bargain Seeker","General"))))),"General") -> At Risk | U14: =IFERROR(INDEX(tblTransactions[ProductCategory],MATCH(A14,tblTransactions[CustomerID],0)),"N/A") -> Grocery
